Workbook

Sheet Read me
A1: Source: Elgin, C., M. A. Kose, F. Ohnsorge, and S. Yu. 2021. “Understanding Informality”, C.E.P.R. Discussion Paper 16497, Centre for Economic Policy Research, London | C1: Download the paper
A2: For questions and comments, please contact Shu Yu (syu2@worldbank.org)
A4: Variables | B4: Labels | C4: Additional notes
A5: Economy | B5: Name
A6: Code | B6: ISO code
A7: DGE_p | B7: Dynamic general equilibrium model-based (DGE) estimates of informal output (% of official GDP) | C7: For data before 1990, please contact the authors
A8: MIMIC_p | B8: Multiple indicators multiple causes model-based (MIMIC) estimates of informal output (% of official GDP)
A9: SEMP_p | B9: Self-employment (% of total employment) | C9: For data before 1990, please contact the authors
A10: Pension_p | B10: Labor force with pension (% of labor force)
A11: Infemp_p | B11: Informal employment (% of total employment; International Labour Organization; hamonized series)
A12: Infsize_p | B12: Employment outside the formal sector (% of total employment; International Labour Organization; hamonized series)
A13: WEF_p | B13: World Economic Forum (WEF) index (1 = least informal, 7 = most informal; reordered). In particular, World Economic Forum conducts surveys and asks, “In your country, how much economic activity do you estimate to be undeclared or unregistered? (1 = Most economic activity is undeclared or unregistered; 7 = Most economic activity is declared or registered)” and reports average responses at the country-year level. Here, the average responses have been reordered to make “7 = Most economic activity is undeclared or unregistered; 1 = Most economic activity is declared or registered.” A higher level suggests a larger informal sector in the country. Data are not verified (Beta version; World Economic Forum. 2008-2018. “Executive Opinion Surveys.”). | C13: Coming soon
A14: WBentp1 | B14: Percent of firms competing against unregistered or informal firms (World Bank Enterprise Surveys)
A15: WBentp2 | B15: Percent of firms formally registered when they started operations in the country (World Bank Enterprise Surveys)
A16: WBentp3 | B16: Number of years firm operated without formal registration (World Bank Enterprise Surveys)
A17: WBentp4 | B17: Percent of firms identifying practices of competitors in the informal sector as a constraint (World Bank Enterprise Surveys)
A18: WVS | B18: Reponses to World Values Survey (WVS) question on "Justifiable: Cheating on taxes" (1 = never justifiable, 10 = always justifiable; simple country averages). WVS asks whether cheating on taxes is justifiable (1 is “never justifiable” and 10 is “always justifiable”) and reports average responses at the country-year level. A higher level suggests that the country is more tolerant toward the informal sector.

Sheet 2005-2015 avg
A1: country | B1: countrycode | C1: Info_DGE | D1: Info_Mimic | E1: Self-emp | F1: Info-empl | G1: out-form-empl
A2: Albania | B2: ALB | C2: =IFERROR(VLOOKUP($B2,DGE_p!$B$2:$AG$157,32,FALSE),"") -> 31.59488 | D2: =IFERROR(VLOOKUP($B2,MIMIC_p!$B$2:$AG$157,32,FALSE),"") -> 33.934313 | E2: =IFERROR(VLOOKUP($B2,SEMP_p!$B$2:$AG$157,32,FALSE),"") -> 59.71904 | F2: =IFERROR(VLOOKUP($B2,Infemp_p!$B$2:$AG$157,32,FALSE),"") -> 63.785 | G2: =IFERROR(VLOOKUP($B2,Infsize_p!$B$2:$AG$157,32,FALSE),"") -> 66.62
A3: Algeria | B3: DZA | C3: =IFERROR(VLOOKUP($B3,DGE_p!$B$2:$AG$157,32,FALSE),"") -> 30.313398 | D3: =IFERROR(VLOOKUP($B3,MIMIC_p!$B$2:$AG$157,32,FALSE),"") -> 31.787115 | E3: =IFERROR(VLOOKUP($B3,SEMP_p!$B$2:$AG$157,32,FALSE),"") -> 33.160285 | F3: =IFERROR(VLOOKUP($B3,Infemp_p!$B$2:$AG$157,32,FALSE),"") | G3: =IFERROR(VLOOKUP($B3,Infsize_p!$B$2:$AG$157,32,FALSE),"")
A4: Angola | B4: AGO | C4: =IFERROR(VLOOKUP($B4,DGE_p!$B$2:$AG$157,32,FALSE),"") -> 41.059401 | D4: =IFERROR(VLOOKUP($B4,MIMIC_p!$B$2:$AG$157,32,FALSE),"") -> 44.133583 | E4: =IFERROR(VLOOKUP($B4,SEMP_p!$B$2:$AG$157,32,FALSE),"") -> 68.098417 | F4: =IFERROR(VLOOKUP($B4,Infemp_p!$B$2:$AG$157,32,FALSE),"") -> 84.32 | G4: =IFERROR(VLOOKUP($B4,Infsize_p!$B$2:$AG$157,32,FALSE),"") -> 76.19
A5: Antigua and Barbuda | B5: ATG | C5: =IFERROR(VLOOKUP($B5,DGE_p!$B$2:$AG$157,32,FALSE),"") | D5: =IFERROR(VLOOKUP($B5,MIMIC_p!$B$2:$AG$157,32,FALSE),"") | E5: =IFERROR(VLOOKUP($B5,SEMP_p!$B$2:$AG$157,32,FALSE),"") | F5: =IFERROR(VLOOKUP($B5,Infemp_p!$B$2:$AG$157,32,FALSE),"") | G5: =IFERROR(VLOOKUP($B5,Infsize_p!$B$2:$AG$157,32,FALSE),"")
A6: Argentina | B6: ARG | C6: =IFERROR(VLOOKUP($B6,DGE_p!$B$2:$AG$157,32,FALSE),"") -> 22.392825 | D6: =IFERROR(VLOOKUP($B6,MIMIC_p!$B$2:$AG$157,32,FALSE),"") -> 24.250676 | E6: =IFERROR(VLOOKUP($B6,SEMP_p!$B$2:$AG$157,32,FALSE),"") -> 23.481158 | F6: =IFERROR(VLOOKUP($B6,Infemp_p!$B$2:$AG$157,32,FALSE),"") -> 50.167778 | G6: =IFERROR(VLOOKUP($B6,Infsize_p!$B$2:$AG$157,32,FALSE),"") -> 43.514444
A7: Armenia | B7: ARM | C7: =IFERROR(VLOOKUP($B7,DGE_p!$B$2:$AG$157,32,FALSE),"") -> 39.004612 | D7: =IFERROR(VLOOKUP($B7,MIMIC_p!$B$2:$AG$157,32,FALSE),"") -> 43.467533 | E7: =IFERROR(VLOOKUP($B7,SEMP_p!$B$2:$AG$157,32,FALSE),"") -> 37.949815 | F7: =IFERROR(VLOOKUP($B7,Infemp_p!$B$2:$AG$157,32,FALSE),"") -> 57.387143 | G7: =IFERROR(VLOOKUP($B7,Infsize_p!$B$2:$AG$157,32,FALSE),"") -> 48.615
A8: Aruba | B8: ABW | C8: =IFERROR(VLOOKUP($B8,DGE_p!$B$2:$AG$157,32,FALSE),"") | D8: =IFERROR(VLOOKUP($B8,MIMIC_p!$B$2:$AG$157,32,FALSE),"") | E8: =IFERROR(VLOOKUP($B8,SEMP_p!$B$2:$AG$157,32,FALSE),"") -> 9.3499999 | F8: =IFERROR(VLOOKUP($B8,Infemp_p!$B$2:$AG$157,32,FALSE),"") | G8: =IFERROR(VLOOKUP($B8,Infsize_p!$B$2:$AG$157,32,FALSE),"")
A9: Australia | B9: AUS | C9: =IFERROR(VLOOKUP($B9,DGE_p!$B$2:$AG$157,32,FALSE),"") -> 13.184101 | D9: =IFERROR(VLOOKUP($B9,MIMIC_p!$B$2:$AG$157,32,FALSE),"") -> 13.742927 | E9: =IFERROR(VLOOKUP($B9,SEMP_p!$B$2:$AG$157,32,FALSE),"") -> 11.178879 | F9: =IFERROR(VLOOKUP($B9,Infemp_p!$B$2:$AG$157,32,FALSE),"") | G9: =IFERROR(VLOOKUP($B9,Infsize_p!$B$2:$AG$157,32,FALSE),"")
A10: Austria | B10: AUT | C10: =IFERROR(VLOOKUP($B10,DGE_p!$B$2:$AG$157,32,FALSE),"") -> 9.4159414 | D10: =IFERROR(VLOOKUP($B10,MIMIC_p!$B$2:$AG$157,32,FALSE),"") -> 9.8223837 | E10: =IFERROR(VLOOKUP($B10,SEMP_p!$B$2:$AG$157,32,FALSE),"") -> 13.31798 | F10: =IFERROR(VLOOKUP($B10,Infemp_p!$B$2:$AG$157,32,FALSE),"") | G10: =IFERROR(VLOOKUP($B10,Infsize_p!$B$2:$AG$157,32,FALSE),"")
A11: Azerbaijan | B11: AZE | C11: =IFERROR(VLOOKUP($B11,DGE_p!$B$2:$AG$157,32,FALSE),"") -> 47.750231 | D11: =IFERROR(VLOOKUP($B11,MIMIC_p!$B$2:$AG$157,32,FALSE),"") -> 54.584806 | E11: =IFERROR(VLOOKUP($B11,SEMP_p!$B$2:$AG$157,32,FALSE),"") -> 63.369015 | F11: =IFERROR(VLOOKUP($B11,Infemp_p!$B$2:$AG$157,32,FALSE),"") | G11: =IFERROR(VLOOKUP($B11,Infsize_p!$B$2:$AG$157,32,FALSE),"")
A12: Bahamas, The | B12: BHS | C12: =IFERROR(VLOOKUP($B12,DGE_p!$B$2:$AG$157,32,FALSE),"") -> 25.560263 | D12: =IFERROR(VLOOKUP($B12,MIMIC_p!$B$2:$AG$157,32,FALSE),"") -> 28.65132 | E12: =IFERROR(VLOOKUP($B12,SEMP_p!$B$2:$AG$157,32,FALSE),"") -> 13.657118 | F12: =IFERROR(VLOOKUP($B12,Infemp_p!$B$2:$AG$157,32,FALSE),"") | G12: =IFERROR(VLOOKUP($B12,Infsize_p!$B$2:$AG$157,32,FALSE),"")
A13: Bahrain | B13: BHR | C13: =IFERROR(VLOOKUP($B13,DGE_p!$B$2:$AG$157,32,FALSE),"") -> 16.470226 | D13: =IFERROR(VLOOKUP($B13,MIMIC_p!$B$2:$AG$157,32,FALSE),"") -> 19.599456 | E13: =IFERROR(VLOOKUP($B13,SEMP_p!$B$2:$AG$157,32,FALSE),"") -> 4.3941081 | F13: =IFERROR(VLOOKUP($B13,Infemp_p!$B$2:$AG$157,32,FALSE),"") | G13: =IFERROR(VLOOKUP($B13,Infsize_p!$B$2:$AG$157,32,FALSE),"")
... A178: Zimbabwe | B178: ZWE | C178: =IFERROR(VLOOKUP($B178,DGE_p!$B$2:$AG$157,32,FALSE),"") -> 63.512866 | D178: =IFERROR(VLOOKUP($B178,MIMIC_p!$B$2:$AG$157,32,FALSE),"") | E178: =IFERROR(VLOOKUP($B178,SEMP_p!$B$2:$AG$157,32,FALSE),"") | F178: =IFERROR(VLOOKUP($B178,Infemp_p!$B$2:$AG$157,32,FALSE),"") -> 86.485 | G178: =IFERROR(VLOOKUP($B178,Infsize_p!$B$2:$AG$157,32,FALSE),"") -> 78.32

Sheet 2003
A1: country | B1: countrycode | C1: Info_DGE | D1: Self-emp
A2: Albania | B2: ALB | C2: =IFERROR(VLOOKUP($B2,DGE_p!$B$2:$P$157,15,FALSE),"") -> 34.009563 | D2: =IF(ISBLANK(VLOOKUP($B2,SEMP_p!$B$2:$P$157,15,FALSE)),"",(VLOOKUP($B2,SEMP_p!$B$2:$P$157,15,FALSE))) -> 66.666664
A3: Algeria | B3: DZA | C3: =IFERROR(VLOOKUP($B3,DGE_p!$B$2:$P$157,15,FALSE),"") -> 30.419153 | D3: =IF(ISBLANK(VLOOKUP($B3,SEMP_p!$B$2:$P$157,15,FALSE)),"",(VLOOKUP($B3,SEMP_p!$B$2:$P$157,15,FALSE))) -> 34.999977
A4: Angola | B4: AGO | C4: =IFERROR(VLOOKUP($B4,DGE_p!$B$2:$P$157,15,FALSE),"") -> 41.197376 | D4: =IF(ISBLANK(VLOOKUP($B4,SEMP_p!$B$2:$P$157,15,FALSE)),"",(VLOOKUP($B4,SEMP_p!$B$2:$P$157,15,FALSE)))
A5: Antigua and Barbuda | B5: ATG | C5: =IFERROR(VLOOKUP($B5,DGE_p!$B$2:$P$157,15,FALSE),"") | D5: =IF(ISBLANK(VLOOKUP($B5,SEMP_p!$B$2:$P$157,15,FALSE)),"",(VLOOKUP($B5,SEMP_p!$B$2:$P$157,15,FALSE)))
A6: Argentina | B6: ARG | C6: =IFERROR(VLOOKUP($B6,DGE_p!$B$2:$P$157,15,FALSE),"") -> 22.924101 | D6: =IF(ISBLANK(VLOOKUP($B6,SEMP_p!$B$2:$P$157,15,FALSE)),"",(VLOOKUP($B6,SEMP_p!$B$2:$P$157,15,FALSE))) -> 26.299999
A7: Armenia | B7: ARM | C7: =IFERROR(VLOOKUP($B7,DGE_p!$B$2:$P$157,15,FALSE),"") -> 45.070461 | D7: =IF(ISBLANK(VLOOKUP($B7,SEMP_p!$B$2:$P$157,15,FALSE)),"",(VLOOKUP($B7,SEMP_p!$B$2:$P$157,15,FALSE))) -> 51.119537
A8: Aruba | B8: ABW | C8: =IFERROR(VLOOKUP($B8,DGE_p!$B$2:$P$157,15,FALSE),"") | D8: =IF(ISBLANK(VLOOKUP($B8,SEMP_p!$B$2:$P$157,15,FALSE)),"",(VLOOKUP($B8,SEMP_p!$B$2:$P$157,15,FALSE)))
A9: Australia | B9: AUS | C9: =IFERROR(VLOOKUP($B9,DGE_p!$B$2:$P$157,15,FALSE),"") -> 13.898851 | D9: =IF(ISBLANK(VLOOKUP($B9,SEMP_p!$B$2:$P$157,15,FALSE)),"",(VLOOKUP($B9,SEMP_p!$B$2:$P$157,15,FALSE))) -> 13.12908
A10: Austria | B10: AUT | C10: =IFERROR(VLOOKUP($B10,DGE_p!$B$2:$P$157,15,FALSE),"") -> 9.6159573 | D10: =IF(ISBLANK(VLOOKUP($B10,SEMP_p!$B$2:$P$157,15,FALSE)),"",(VLOOKUP($B10,SEMP_p!$B$2:$P$157,15,FALSE))) -> 13
A11: Azerbaijan | B11: AZE | C11: =IFERROR(VLOOKUP($B11,DGE_p!$B$2:$P$157,15,FALSE),"") -> 57.314213 | D11: =IF(ISBLANK(VLOOKUP($B11,SEMP_p!$B$2:$P$157,15,FALSE)),"",(VLOOKUP($B11,SEMP_p!$B$2:$P$157,15,FALSE))) -> 67.300003
A12: Bahamas, The | B12: BHS | C12: =IFERROR(VLOOKUP($B12,DGE_p!$B$2:$P$157,15,FALSE),"") -> 27.20505 | D12: =IF(ISBLANK(VLOOKUP($B12,SEMP_p!$B$2:$P$157,15,FALSE)),"",(VLOOKUP($B12,SEMP_p!$B$2:$P$157,15,FALSE))) -> 14.3
A13: Bahrain | B13: BHR | C13: =IFERROR(VLOOKUP($B13,DGE_p!$B$2:$P$157,15,FALSE),"") -> 16.532934 | D13: =IF(ISBLANK(VLOOKUP($B13,SEMP_p!$B$2:$P$157,15,FALSE)),"",(VLOOKUP($B13,SEMP_p!$B$2:$P$157,15,FALSE))) -> 4.0999999
... A178: Zimbabwe | B178: ZWE | C178: =IFERROR(VLOOKUP($B178,DGE_p!$B$2:$P$157,15,FALSE),"") -> 60.036434 | D178: =IF(ISBLANK(VLOOKUP($B178,SEMP_p!$B$2:$P$157,15,FALSE)),"",(VLOOKUP($B178,SEMP_p!$B$2:$P$157,15,FALSE))) -> #N/A

Sheet DGE_p
A1: Economy | B1: Code | C1: 1990 | D1: 1991 | E1: 1992 | F1: 1993 | G1: 1994 | H1: 1995 | I1: 1996 | J1: 1997 | K1: 1998 | L1: 1999 | M1: 2000 | N1: 2001 | O1: 2002 | P1: 2003 | Q1: 2004 | R1: 2005 | S1: 2006 | T1: 2007 | U1: 2008 | V1: 2009 | W1: 2010 | X1: 2011 | Y1: 2012 | Z1: 2013 | AA1: 2014 | AB1: 2015 | AC1: 2016 | AD1: 2017 | AE1: 2018 | AG1: avg 2005-2015
A2: Albania | B2: ALB | C2: 36.205364 | D2: 35.997807 | E2: 34.999146 | F2: 35.049511 | G2: 35.42675 | H2: 35.058449 | I2: 34.621914 | J2: 33.991074 | K2: 33.554165 | L2: 33.908962 | M2: 34.238525 | N2: 34.112099 | O2: 34.013187 | P2: 34.009563 | Q2: 33.790798 | R2: 33.603615 | S2: 33.305096 | T2: 32.900143 | U2: 32.241131 | V2: 31.42392 | W2: 31.049883 | X2: 30.881023 | Y2: 30.871901 | Z2: 30.445469 | AA2: 30.318991 | AB2: 30.50251 | AC2: 30.69953 | AD2: 30.708265 | AE2: 30.437105 | AG2: =AVERAGE($R2:$AB2) -> 31.59488
A3: Algeria | B3: DZA | C3: 29.969116 | D3: 29.916943 | E3: 29.884853 | F3: 29.829243 | G3: 29.822683 | H3: 30.067387 | I3: 30.239305 | J3: 30.240721 | K3: 30.340803 | L3: 30.356846 | M3: 30.579885 | N3: 30.722147 | O3: 30.743202 | P3: 30.419153 | Q3: 31.21817 | R3: 31.344526 | S3: 31.700745 | T3: 31.201611 | U3: 31.092617 | V3: 30.61553 | W3: 30.480278 | X3: 29.916107 | Y3: 29.825583 | Z3: 29.697721 | AA3: 28.966862 | AB3: 28.605795 | AC3: 28.34787 | AD3: 28.090626 | AE3: 27.907875 | AG3: =AVERAGE($R3:$AB3) -> 30.313398
A4: Angola | B4: AGO | C4: 42.032562 | D4: 41.262264 | E4: 41.184803 | F4: 41.579483 | G4: 41.12796 | H4: 40.200756 | I4: 40.757286 | J4: 39.612217 | K4: 40.025669 | L4: 38.995441 | M4: 39.755108 | N4: 40.571007 | O4: 40.93816 | P4: 41.197376 | Q4: 41.49712 | R4: 41.892601 | S4: 42.141041 | T4: 42.104332 | U4: 41.841858 | V4: 41.295341 | W4: 41.350643 | X4: 41.083103 | Y4: 40.68718 | Z4: 40.049431 | AA4: 39.816345 | AB4: 39.391537 | AC4: 39.207199 | AD4: 39.161381 | AE4: 39.174072 | AG4: =AVERAGE($R4:$AB4) -> 41.059401
A5: Argentina | B5: ARG | C5: 24.348072 | D5: 24.460047 | E5: 24.316475 | F5: 23.949341 | G5: 23.805737 | H5: 23.340496 | I5: 23.018152 | J5: 23.223078 | K5: 23.203182 | L5: 23.084187 | M5: 23.000473 | N5: 22.860527 | O5: 22.686539 | P5: 22.924101 | Q5: 23.152037 | R5: 23.175035 | S5: 23.173586 | T5: 23.000641 | U5: 22.761007 | V5: 22.56385 | W5: 22.411331 | X5: 22.221504 | Y5: 22.056883 | Z5: 21.839558 | AA5: 21.622149 | AB5: 21.495525 | AC5: 21.327438 | AD5: 21.18718 | AE5: 21.145267 | AG5: =AVERAGE($R5:$AB5) -> 22.392825
A6: Armenia | B6: ARM | C6: 43.546524 | D6: 42.666599 | E6: 42.600899 | F6: 43.518177 | G6: 45.792004 | H6: 45.862804 | I6: 46.201385 | J6: 46.896111 | K6: 46.922569 | L6: 46.993225 | M6: 46.882259 | N6: 46.773983 | O6: 45.49472 | P6: 45.070461 | Q6: 44.289856 | R6: 43.571857 | S6: 42.315376 | T6: 41.100563 | U6: 39.944286 | V6: 38.871475 | W6: 38.238056 | X6: 37.617188 | Y6: 37.416019 | Z6: 37.098522 | AA6: 36.771603 | AB6: 36.105789 | AC6: 35.550232 | AD6: 35.33268 | AG6: =AVERAGE($R6:$AB6) -> 39.004612
A7: Australia | B7: AUS | C7: 15.244408 | D7: 15.061095 | E7: 14.935771 | F7: 14.82589 | G7: 14.76512 | H7: 14.723909 | I7: 14.626008 | J7: 14.481968 | K7: 14.371072 | L7: 14.262671 | M7: 14.215001 | N7: 14.114329 | O7: 14.011227 | P7: 13.898851 | Q7: 13.778003 | R7: 13.702364 | S7: 13.596591 | T7: 13.499954 | U7: 13.407648 | V7: 13.272465 | W7: 13.199358 | X7: 13.084046 | Y7: 12.957984 | Z7: 12.848927 | AA7: 12.761232 | AB7: 12.694539 | AC7: 12.638254 | AD7: 12.583068 | AE7: 12.527935 | AG7: =AVERAGE($R7:$AB7) -> 13.184101
A8: Austria | B8: AUT | C8: 10.544946 | D8: 10.459683 | E8: 10.362458 | F8: 10.262081 | G8: 10.179858 | H8: 10.100736 | I8: 10.030376 | J8: 9.9541836 | K8: 9.8871517 | L8: 9.8360147 | M8: 9.7789268 | N8: 9.7156372 | O8: 9.6566792 | P8: 9.6159573 | Q8: 9.5739574 | R8: 9.5441885 | S8: 9.516573 | T8: 9.5001764 | U8: 9.4587898 | V8: 9.3980637 | W8: 9.387991 | X8: 9.3865356 | Y8: 9.3700151 | Z8: 9.3452845 | AA8: 9.350009 | AB8: 9.317729 | AC8: 9.284831 | AD8: 9.2615881 | AE8: 9.2427692 | AG8: =AVERAGE($R8:$AB8) -> 9.4159414
A9: Azerbaijan | B9: AZE | C9: 48.41296 | D9: 49.851406 | E9: 49.52026 | F9: 51.859177 | G9: 56.227505 | H9: 59.337116 | I9: 59.609421 | J9: 59.743492 | K9: 60.283493 | L9: 60.64962 | M9: 60.770004 | N9: 60.518257 | O9: 59.388565 | P9: 57.314213 | Q9: 55.684425 | R9: 54.652458 | S9: 53.280342 | T9: 52.000141 | U9: 50.403042 | V9: 49.168171 | W9: 47.952862 | X9: 46.242271 | Y9: 44.987003 | Z9: 43.483986 | AA9: 42.113556 | AB9: 40.968712 | AC9: 40.378605 | AD9: 39.859467 | AE9: 39.469986 | AG9: =AVERAGE($R9:$AB9) -> 47.750231
A10: Bahamas, The | B10: BHS | C10: 30.808374 | D10: 30.365664 | E10: 30.106243 | F10: 30.199915 | G10: 29.90337 | H10: 29.806984 | I10: 29.566628 | J10: 29.116838 | K10: 28.791508 | L10: 28.401459 | M10: 27.936047 | N10: 27.67309 | O10: 27.441278 | P10: 27.20505 | Q10: 27.086575 | R10: 26.796515 | S10: 26.468355 | T10: 26.200542 | U10: 25.902288 | V10: 25.590897 | W10: 25.483692 | X10: 25.255352 | Y10: 25.124922 | Z10: 24.801674 | AA10: 24.767082 | AB10: 24.771572 | AC10: 24.635792 | AD10: 24.522751 | AG10: =AVERAGE($R10:$AB10) -> 25.560263
A11: Bahrain | B11: BHR | C11: 17.059486 | D11: 16.927078 | E11: 16.725899 | F11: 16.596649 | G11: 16.486298 | H11: 16.424906 | I11: 16.318382 | J11: 16.272091 | K11: 16.094109 | L11: 16.341745 | M11: 16.455021 | N11: 16.455332 | O11: 16.515749 | P11: 16.532934 | Q11: 16.76293 | R11: 17.100025 | S11: 16.963276 | T11: 16.741926 | U11: 17.071676 | V11: 16.792336 | W11: 16.653646 | X11: 16.473623 | Y11: 16.240223 | Z11: 15.952136 | AA11: 15.629813 | AB11: 15.553808 | AC11: 15.524117 | AD11: 15.284875 | AE11: 15.232141 | AG11: =AVERAGE($R11:$AB11) -> 16.470226
A12: Bangladesh | B12: BGD | C12: 42.95211 | D12: 42.664642 | E12: 42.45015 | F12: 42.107204 | G12: 41.800095 | H12: 41.484585 | I12: 41.130989 | J12: 40.773449 | K12: 40.172474 | L12: 39.560257 | M12: 38.955914 | N12: 38.389839 | O12: 37.765057 | P12: 37.09893 | Q12: 36.318214 | R12: 35.509972 | S12: 34.688599 | T12: 34.100784 | U12: 33.480824 | V12: 32.828964 | W12: 32.177204 | X12: 31.500191 | Y12: 30.899021 | Z12: 30.204218 | AA12: 29.5326 | AB12: 28.897316 | AC12: 28.256935 | AD12: 27.631273 | AE12: 26.998659 | AG12: =AVERAGE($R12:$AB12) -> 32.165427
A13: Barbados | B13: BRB | C13: 27.257252 | D13: 26.745813 | E13: 26.592169 | F13: 26.418327 | G13: 26.854389 | H13: 26.656822 | I13: 26.797005 | J13: 26.614597 | K13: 26.373943 | L13: 26.205805 | M13: 26.090532 | N13: 25.695164 | O13: 25.820341 | P13: 25.400028 | Q13: 25.323406 | R13: 25.132286 | S13: 24.697495 | T13: 24.499954 | U13: 24.168461 | V13: 23.806005 | W13: 23.814163 | X13: 23.606796 | Y13: 23.605207 | Z13: 23.500889 | AA13: 23.454325 | AB13: 23.537182 | AC13: 23.611942 | AD13: 23.663586 | AE13: 23.72175 | AG13: =AVERAGE($R13:$AB13) -> 23.983888
A14: Belarus | B14: BLR | C14: 44.36388 | D14: 43.866821 | E14: 43.854977 | F14: 44.071995 | G14: 43.010296 | H14: 42.561867 | I14: 42.91106 | J14: 43.546661 | K14: 43.767567 | L14: 43.947906 | M14: 44.281651 | N14: 44.306721 | O14: 44.415421 | P14: 44.384476 | Q14: 44.32053 | R14: 44.27037 | S14: 43.857151 | T14: 43.300365 | U14: 42.71347 | V14: 41.820137 | W14: 40.916435 | X14: 39.954174 | Y14: 39.573814 | Z14: 39.15316 | AA14: 38.735535 | AB14: 38.361256 | AC14: 38.011654 | AD14: 37.749626 | AE14: 37.454849 | AG14: =AVERAGE($R14:$AB14) -> 41.150534
A15: Belgium | B15: BEL | C15: 22.945543 | D15: 22.792948 | E15: 22.647985 | F15: 22.495502 | G15: 22.371479 | H15: 22.324093 | I15: 22.211817 | J15: 22.081999 | K15: 22.005472 | L15: 21.922796 | M15: 21.84734 | N15: 21.74255 | O15: 21.611916 | P15: 21.535511 | Q15: 21.542747 | R15: 21.488173 | S15: 21.378532 | T15: 21.301054 | U15: 21.184193 | V15: 21.050579 | W15: 20.99044 | X15: 20.906097 | Y15: 20.821095 | Z15: 20.731125 | AA15: 20.664415 | AB15: 20.617481 | AC15: 20.576616 | AD15: 20.51601 | AE15: 20.431688 | AG15: =AVERAGE($R15:$AB15) -> 21.012108
A16: Belize | B16: BLZ | C16: 46.856544 | D16: 45.879032 | E16: 43.849052 | F16: 43.4277 | G16: 42.965351 | H16: 42.727489 | I16: 42.430626 | J16: 42.56422 | K16: 42.634491 | L16: 42.715614 | M16: 42.28643 | N16: 41.946079 | O16: 41.470837 | P16: 41.619389 | Q16: 41.770378 | R16: 41.642128 | S16: 41.848312 | T16: 42.000206 | U16: 41.56311 | V16: 41.480591 | W16: 41.664883 | X16: 41.910175 | Y16: 41.824581 | Z16: 41.798203 | AA16: 41.460419 | AB16: 41.01638 | AC16: 40.745407 | AD16: 39.975842 | AG16: =AVERAGE($R16:$AB16) -> 41.655363
A17: Benin | B17: BEN | C17: 48.71286 | D17: 49.178192 | E17: 49.48745 | F17: 49.769852 | G17: 49.948307 | H17: 49.880215 | I17: 50.052326 | J17: 50.030415 | K17: 49.963829 | L17: 49.934212 | M17: 49.934093 | N17: 49.736233 | O17: 49.686535 | P17: 49.444447 | Q17: 49.360538 | R17: 49.285549 | S17: 49.247334 | T17: 49.100082 | U17: 48.776783 | V17: 48.445538 | W17: 48.209648 | X17: 47.778683 | Y17: 47.507172 | Z17: 46.858826 | AA17: 46.483707 | AB17: 45.999615 | AC17: 45.690987 | AD17: 45.347534 | AG17: =AVERAGE($R17:$AB17) -> 47.972085
A18: Bhutan | B18: BTN | C18: 37.508007 | D18: 37.385643 | E18: 36.575935 | F18: 35.412674 | G18: 34.657684 | H18: 33.511395 | I18: 32.7924 | J18: 32.342957 | K18: 32.157455 | L18: 31.967968 | M18: 30.851597 | N18: 30.119169 | O18: 29.593489 | P18: 29.007727 | Q18: 28.537146 | R18: 27.55928 | S18: 27.618519 | T18: 27.702709 | U18: 27.694078 | V18: 27.202606 | W18: 26.533531 | X18: 25.754595 | Y18: 24.946692 | Z18: 24.937002 | AA18: 24.390015 | AB18: 24.108498 | AC18: 23.692278 | AD18: 23.212225 | AG18: =AVERAGE($R18:$AB18) -> 26.222502
A19: Bolivia | B19: BOL | C19: 67.66375 | D19: 67.477654 | E19: 66.916595 | F19: 66.387787 | G19: 66.450714 | H19: 65.968307 | I19: 65.565666 | J19: 65.021095 | K19: 63.959534 | L19: 63.419502 | M19: 63.283432 | N19: 63.417454 | O19: 63.389301 | P19: 63.396126 | Q19: 63.948708 | R19: 63.77713 | S19: 63.720955 | T19: 63.500099 | U19: 63.21777 | V19: 62.57193 | W19: 62.297707 | X19: 61.405884 | Y19: 60.071087 | Z19: 59.077625 | AA19: 58.322655 | AB19: 56.493515 | AC19: 55.710876 | AD19: 54.768753 | AE19: 53.825726 | AG19: =AVERAGE($R19:$AB19) -> 61.314214
A20: Bosnia and Herzegovina | B20: BIH | C20: 47.675121 | D20: 48.774036 | E20: 47.455086 | F20: 50.015076 | G20: 50.16188 | H20: 50.050102 | I20: 47.806061 | J20: 44.981079 | K20: 42.51305 | L20: 40.544361 | M20: 39.086781 | N20: 38.080944 | O20: 37.031097 | P20: 35.892284 | Q20: 34.954281 | R20: 34.037945 | S20: 33.301701 | T20: 32.800629 | U20: 32.161545 | V20: 31.379128 | W20: 30.894014 | X20: 30.303595 | Y20: 29.950279 | Z20: 29.755821 | AA20: 29.30991 | AB20: 29.088318 | AC20: 28.67528 | AD20: 28.477617 | AE20: 28.149969 | AG20: =AVERAGE($R20:$AB20) -> 31.180262
A21: Botswana | B21: BWA | C21: 40.517189 | D21: 40.006645 | E21: 39.112778 | F21: 38.386875 | G21: 37.661823 | H21: 37.338226 | I21: 36.22403 | J21: 36.538963 | K21: 35.53233 | L21: 35.408695 | M21: 34.630714 | N21: 33.686943 | O21: 33.711655 | P21: 32.566307 | Q21: 32.608757 | R21: 32.49432 | S21: 31.893238 | T21: 31.901402 | U21: 31.376865 | V21: 30.77681 | W21: 29.910166 | X21: 29.790371 | Y21: 29.264757 | Z21: 28.774374 | AA21: 28.193695 | AB21: 27.675236 | AC21: 27.194241 | AD21: 26.827049 | AG21: =AVERAGE($R21:$AB21) -> 30.186476
A22: Brazil | B22: BRA | C22: 38.83725 | D22: 38.496964 | E22: 38.099743 | F22: 37.727962 | G22: 37.249355 | H22: 36.654919 | I22: 35.693657 | J22: 35.78199 | K22: 35.58289 | L22: 35.85989 | M22: 36.015575 | N22: 35.906792 | O22: 36.033073 | P22: 36.023487 | Q22: 36.226128 | R22: 36.279827 | S22: 36.209248 | T22: 36.004292 | U22: 35.742767 | V22: 35.421604 | W22: 35.14278 | X22: 34.814896 | Y22: 34.474094 | Z22: 34.143326 | AA22: 33.952003 | AB22: 33.738918 | AC22: 33.469604 | AD22: 33.369141 | AE22: 33.369675 | AG22: =AVERAGE($R22:$AB22) -> 35.083978
A23: Brunei Darussalam | B23: BRN | C23: 33.114754 | D23: 32.762238 | E23: 32.957329 | F23: 32.350433 | G23: 31.958139 | H23: 31.514389 | I23: 30.991291 | J23: 30.440798 | K23: 30.195852 | L23: 30.501089 | M23: 30.899599 | N23: 30.72374 | O23: 30.816082 | P23: 31.042437 | Q23: 31.177187 | R23: 31.448475 | S23: 31.47654 | T23: 31.20093 | U23: 31.124874 | V23: 30.651691 | W23: 30.593256 | X23: 30.604809 | Y23: 30.045357 | Z23: 29.353085 | AA23: 28.988111 | AB23: 28.560213 | AC23: 28.366333 | AD23: 28.126997 | AG23: =AVERAGE($R23:$AB23) -> 30.36794
A24: Bulgaria | B24: BGR | C24: 39.182384 | D24: 38.958534 | E24: 39.026669 | F24: 38.813381 | G24: 39.372112 | H24: 39.59407 | I24: 40.5956 | J24: 39.988472 | K24: 39.236565 | L24: 38.384087 | M24: 37.539318 | N24: 36.715092 | O24: 36.061207 | P24: 35.41597 | Q24: 34.9231 | R24: 34.307049 | S24: 33.478436 | T24: 32.700512 | U24: 31.587261 | V24: 30.84243 | W24: 30.174355 | X24: 29.825583 | Y24: 29.436537 | Z24: 29.05941 | AA24: 28.863358 | AB24: 28.642199 | AC24: 28.509586 | AD24: 28.29052 | AE24: 27.84833 | AG24: =AVERAGE($R24:$AB24) -> 30.810648
A25: Burkina Faso | B25: BFA | C25: 49.224998 | D25: 48.576691 | E25: 47.963905 | F25: 47.539986 | G25: 46.543362 | H25: 46.147785 | I25: 45.713547 | J25: 45.123302 | K25: 44.561222 | L25: 44.346985 | M25: 43.77776 | N25: 43.242165 | O25: 42.759796 | P25: 42.236492 | Q25: 41.618301 | R25: 40.918411 | S25: 40.374088 | T25: 39.600021 | U25: 38.964077 | V25: 38.176846 | W25: 37.266392 | X25: 36.167015 | Y25: 35.034637 | Z25: 33.955555 | AA25: 33.212013 | AB25: 32.638618 | AC25: 32.003525 | AD25: 31.639021 | AE25: 31.202633 | AG25: =AVERAGE($R25:$AB25) -> 36.937061
A26: Burundi | B26: BDI | C26: 39.916046 | D26: 40.003864 | E26: 39.987774 | F26: 39.910984 | G26: 40.240879 | H26: 40.354836 | I26: 40.389015 | J26: 40.501099 | K26: 40.54488 | L26: 40.180702 | M26: 39.909676 | N26: 39.887794 | O26: 40.118584 | P26: 39.970367 | Q26: 39.590538 | R26: 39.405449 | S26: 39.571907 | T26: 39.600975 | U26: 39.391258 | V26: 39.209633 | W26: 38.724407 | X26: 38.423321 | Y26: 37.873348 | Z26: 37.301571 | AA26: 36.960056 | AB26: 36.829334 | AC26: 36.618176 | AD26: 36.633827 | AG26: =AVERAGE($R26:$AB26) -> 38.481024
A27: Cabo Verde | B27: CPV | C27: 39.474937 | D27: 39.278534 | E27: 39.001266 | F27: 38.72332 | G27: 38.445366 | H27: 37.984119 | I27: 37.867821 | J27: 37.396057 | K27: 37.265045 | L27: 36.839832 | M27: 36.871109 | N27: 36.470943 | O27: 36.01886 | P27: 35.554199 | Q27: 35.045185 | R27: 34.555908 | S27: 34.166882 | T27: 33.400978 | U27: 32.753857 | V27: 32.20916 | W27: 31.6059 | X27: 31.037764 | Y27: 30.813725 | Z27: 30.581778 | AA27: 30.266798 | AB27: 30.136936 | AC27: 30.035601 | AD27: 29.907257 | AG27: =AVERAGE($R27:$AB27) -> 31.957244
A28: Cambodia | B28: KHM | C28: 54.448174 | D28: 54.436195 | E28: 54.348396 | F28: 54.207115 | G28: 53.766678 | H28: 53.636124 | I28: 53.247417 | J28: 52.975227 | K28: 52.9105 | L28: 52.282055 | M28: 51.429932 | N28: 50.988503 | O28: 49.687981 | P28: 48.867737 | Q28: 48.260567 | R28: 47.559456 | S28: 46.886913 | T28: 46.003181 | U28: 45.10677 | V28: 44.01096 | W28: 43.337151 | X28: 42.698807 | Y28: 41.851089 | Z28: 40.943939 | AA28: 40.023022 | AB28: 39.15937 | AC28: 38.219322 | AD28: 37.397949 | AE28: 36.601799 | AG28: =AVERAGE($R28:$AB28) -> 43.416423
A29: Cameroon | B29: CMR | C29: 32.145084 | D29: 32.248161 | E29: 32.515553 | F29: 32.56929 | G29: 32.596416 | H29: 32.680553 | I29: 32.697388 | J29: 32.643623 | K29: 32.551571 | L29: 32.441441 | M29: 32.325916 | N29: 32.056572 | O29: 31.873142 | P29: 31.774553 | Q29: 31.619507 | R29: 31.495327 | S29: 31.459803 | T29: 31.400707 | U29: 31.17371 | V29: 30.983761 | W29: 30.796381 | X29: 30.572165 | Y29: 30.340586 | Z29: 30.080854 | AA29: 29.800024 | AB29: 29.519197 | AC29: 29.23238 | AD29: 28.971619 | AE29: 28.692249 | AG29: =AVERAGE($R29:$AB29) -> 30.692956
A30: Canada | B30: CAN | C30: 16.751848 | D30: 16.527992 | E30: 16.382053 | F30: 16.304913 | G30: 16.265739 | H30: 16.231861 | I30: 16.174135 | J30: 16.093176 | K30: 16.019085 | L30: 15.976177 | M30: 15.931149 | N30: 15.814813 | O30: 15.764874 | P30: 15.699037 | Q30: 15.617551 | R30: 15.522237 | S30: 15.39958 | T30: 15.300814 | U30: 15.190259 | V30: 15.001069 | W30: 14.949337 | X30: 14.891535 | Y30: 14.777857 | Z30: 14.687094 | AA30: 14.582059 | AB30: 14.48711 | AC30: 14.409974 | AD30: 14.362709 | AE30: 14.296511 | AG30: =AVERAGE($R30:$AB30) -> 14.980814
A31: Central African Republic | B31: CAF | C31: 42.216221 | D31: 42.080654 | E31: 42.079041 | F31: 42.495708 | G31: 42.547802 | H31: 42.66256 | I31: 43.388359 | J31: 43.724613 | K31: 43.988148 | L31: 43.416801 | M31: 43.525867 | N31: 43.804966 | O31: 43.907955 | P31: 43.454311 | Q31: 44.774391 | R31: 44.792439 | S31: 44.936989 | T31: 45.100323 | U31: 45.163162 | V31: 45.215954 | W31: 45.127983 | X31: 45.110439 | Y31: 44.96228 | Z31: 44.912251 | AA31: 45.227402 | AB31: 45.205124 | AC31: 45.371334 | AD31: 45.641644 | AG31: =AVERAGE($R31:$AB31) -> 45.068577
A32: Chad | B32: TCD | C32: 49.842854 | D32: 49.937191 | E32: 49.985703 | F32: 50.0741 | G32: 50.238735 | H32: 50.445675 | I32: 50.577797 | J32: 50.771881 | K32: 50.870823 | L32: 50.884228 | M32: 50.920982 | N32: 49.692928 | O32: 47.125526 | P32: 45.810749 | Q32: 45.107384 | R32: 44.362907 | S32: 43.125504 | T32: 42.202969 | U32: 41.400421 | V32: 40.627365 | W32: 39.951618 | X32: 38.706219 | Y32: 37.814472 | Z32: 37.062153 | AA32: 36.663414 | AB32: 36.441494 | AC32: 36.477669 | AD32: 36.392059 | AG32: =AVERAGE($R32:$AB32) -> 39.850776
A33: Chile | B33: CHL | C33: 23.080687 | D33: 22.842073 | E33: 22.666567 | F33: 22.438513 | G33: 22.037823 | H33: 21.595406 | I33: 21.136936 | J33: 20.77663 | K33: 20.463835 | L33: 20.159603 | M33: 19.975742 | N33: 19.755571 | O33: 19.581739 | P33: 19.479156 | Q33: 19.305035 | R33: 19.095335 | S33: 18.800243 | T33: 18.501404 | U33: 18.141232 | V33: 17.769241 | W33: 17.656096 | X33: 17.426247 | Y33: 17.151617 | Z33: 17.011036 | AA33: 16.797915 | AB33: 16.582535 | AC33: 16.383677 | AD33: 16.219604 | AE33: 16.053699 | AG33: =AVERAGE($R33:$AB33) -> 17.721173
A34: China | B34: CHN | C34: 18.887648 | D34: 18.606062 | E34: 18.165237 | F34: 17.614136 | G34: 17.145937 | H34: 16.753712 | I34: 16.320757 | J34: 15.849586 | K34: 15.354788 | L34: 14.897082 | M34: 14.507929 | N34: 14.144794 | O34: 13.774612 | P34: 13.379285 | Q34: 12.981783 | R34: 12.565181 | S34: 12.219555 | T34: 11.90016 | U34: 11.574294 | V34: 11.18231 | W34: 10.803558 | X34: 10.445053 | Y34: 10.102781 | Z34: 9.7755537 | AA34: 9.4836664 | AB34: 9.2126112 | AC34: 8.9545231 | AD34: 8.720561 | AE34: 8.5519781 | AG34: =AVERAGE($R34:$AB34) -> 10.842248
A35: Colombia | B35: COL | C35: 35.384995 | D35: 35.59803 | E35: 35.386284 | F35: 35.288101 | G35: 35.003986 | H35: 34.867432 | I35: 34.450432 | J35: 34.181263 | K35: 33.901314 | L35: 33.76001 | M35: 34.213039 | N35: 34.264191 | O35: 34.273071 | P35: 34.44043 | Q35: 34.271919 | R35: 34.198036 | S35: 33.817917 | T35: 33.50111 | U35: 33.213051 | V35: 33.116524 | W35: 32.982464 | X35: 32.781334 | Y35: 32.475613 | Z35: 32.019993 | AA35: 31.600042 | AB35: 31.215885 | AC35: 30.822096 | AD35: 30.457726 | AE35: 30.160215 | AG35: =AVERAGE($R35:$AB35) -> 32.811088
A36: Comoros | B36: COM | C36: 35.770386 | D36: 35.86158 | E36: 36.266945 | F36: 36.442516 | G36: 36.575951 | H36: 36.762081 | I36: 37.040508 | J36: 37.218559 | K36: 37.269367 | L36: 37.495552 | M36: 37.663204 | N36: 37.811596 | O36: 37.929096 | P36: 38.248123 | Q36: 38.489368 | R36: 38.883255 | S36: 39.173935 | T36: 39.401051 | U36: 39.743813 | V36: 39.982426 | W36: 40.475155 | X36: 40.709621 | Y36: 40.756023 | Z36: 40.977512 | AA36: 41.029926 | AB36: 41.223801 | AC36: 41.367062 | AD36: 41.421501 | AG36: =AVERAGE($R36:$AB36) -> 40.214229
A37: Congo, Dem. Rep. | B37: COD | C37: 38.501083 | D37: 39.097675 | E37: 38.56789 | F37: 39.725853 | G37: 43.10833 | H37: 43.339516 | I37: 43.824715 | J37: 44.029724 | K37: 44.977539 | L37: 45.38287 | M37: 45.662899 | N37: 46.181049 | O37: 46.082008 | P37: 46.392601 | Q37: 46.346851 | R37: 46.339149 | S37: 46.492619 | T37: 46.701015 | U37: 46.698303 | V37: 46.746887 | W37: 46.193844 | X37: 45.453896 | Y37: 44.587624 | Z37: 44.063835 | AA37: 43.535378 | AB37: 43.256413 | AC37: 43.131561 | AD37: 43.015312 | AE37: 42.388538 | AG37: =AVERAGE($R37:$AB37) -> 45.460815
A38: Congo, Rep. | B38: COG | C38: 42.402061 | D38: 41.673367 | E38: 41.577335 | F38: 41.70023 | G38: 43.003914 | H38: 44.285267 | I38: 44.87286 | J38: 44.079575 | K38: 44.471436 | L38: 45.225414 | M38: 46.035633 | N38: 45.946144 | O38: 45.815849 | P38: 45.970123 | Q38: 46.267166 | R38: 46.49733 | S38: 46.256386 | T38: 44.600479 | U38: 45.154301 | V38: 44.79924 | W38: 44.023342 | X38: 43.395157 | Y38: 42.067036 | Z38: 39.855247 | AA38: 39.166134 | AB38: 39.048409 | AC38: 38.961388 | AD38: 39.039665 | AG38: =AVERAGE($R38:$AB38) -> 43.169369
A39: Costa Rica | B39: CRI | C39: 27.7766 | D39: 27.521774 | E39: 27.332788 | F39: 27.131001 | G39: 26.892916 | H39: 26.615486 | I39: 26.224693 | J39: 26.146528 | K39: 25.912863 | L39: 25.486279 | M39: 25.233009 | N39: 25.14098 | O39: 24.864635 | P39: 24.65642 | Q39: 24.395798 | R39: 24.386206 | S39: 24.177971 | T39: 24.008408 | U39: 23.599577 | V39: 23.214672 | W39: 22.83098 | X39: 22.456594 | Y39: 22.484833 | Z39: 22.209871 | AA39: 22.008444 | AB39: 21.732321 | AC39: 21.367599 | AD39: 21.30085 | AE39: 21.114775 | AG39: =AVERAGE($R39:$AB39) -> 23.009989
A40: Cote d'Ivoire | B40: CIV | C40: 44.13765 | D40: 44.791344 | E40: 45.2113 | F40: 45.730885 | G40: 46.13871 | H40: 46.401512 | I40: 46.434586 | J40: 46.392475 | K40: 46.806301 | L40: 46.627541 | M40: 46.805717 | N40: 46.958557 | O40: 46.969379 | P40: 47.183907 | Q40: 47.131508 | R40: 47.157963 | S40: 47.172203 | T40: 47.005329 | U40: 46.804489 | V40: 46.651115 | W40: 46.32848 | X40: 46.49971 | Y40: 46.321083 | Z40: 45.767433 | AA40: 45.020206 | AB40: 44.260479 | AC40: 43.491848 | AD40: 42.77446 | AE40: 42.042931 | AG40: =AVERAGE($R40:$AB40) -> 46.271681
...

Sheet replication
B1: Bangladesh | D1: Ghana | F1: India | H1: Indonesia | J1: Tanzania
A2: 1990 | B2: 42.95211 | D2: 40.800056 | F2: 26.323105 | H2: 22.722509 | J2: 60.099411 | N2: Bangladesh
A3: 1991 | B3: 42.664642 | D3: 40.412334 | F3: 26.131348 | H3: 22.149334 | J3: 59.252636 | N3: [1] 37.58694 37.23112 37.04267 37.13224 37.06698 36.70058 36.39922 35.28692 35.03954 34.86611
A4: 1992 | B4: 42.45015 | D4: 40.337952 | F4: 25.930332 | H4: 21.719664 | J4: 59.108471 | N4: [11] 34.38856 34.21208 34.52388 34.66083 34.54264 34.54662 34.39772 34.10000 34.13263 34.49483
A5: 1993 | B5: 42.107204 | D5: 40.203869 | F5: 25.727173 | H5: 21.272236 | J5: 59.329712 | N5: [21] 34.82710 34.77867 35.00087 35.09350 35.01844 34.74834 34.43965 34.40974 34.13310
A6: 1994 | B6: 41.800095 | D6: 40.134487 | F6: 25.441801 | H6: 20.87981 | J6: 59.906216
A7: 1995 | B7: 41.484585 | D7: 40.184052 | F7: 25.032356 | H7: 20.250992 | J7: 60.985935 | N7: Ghana
A8: 1996 | B8: 41.130989 | D8: 40.113991 | F8: 24.715343 | H8: 19.952507 | J8: 62.476116 | N8: [1] 48.62283 47.03364 46.74351 46.19760 45.66158 44.53491 43.72257 42.47710 41.90926 40.37918
A9: 1997 | B9: 40.773449 | D9: 40.233707 | F9: 24.362961 | H9: 19.576122 | J9: 62.626118 | N9: [11] 41.20759 41.79611 39.98821 39.74053 38.68860 38.01139 38.11295 38.30000 37.70368 37.16396
A10: 1998 | B10: 40.172474 | D10: 40.116455 | F10: 24.013775 | H10: 19.407167 | J10: 61.850792 | N10: [21] 35.83261 35.27775 32.86561 31.15533 30.82905 30.70140 30.70765 29.03659 28.32580
A11: 1999 | B11: 39.560257 | D11: 40.298923 | F11: 23.624575 | H11: 19.338741 | J11: 61.278652
A12: 2000 | B12: 38.955914 | D12: 39.675777 | F12: 23.38763 | H12: 19.18568 | J12: 60.575043 | N12: India
A13: 2001 | B13: 38.389839 | D13: 39.232029 | F13: 23.158476 | H13: 19.038862 | J13: 59.767296 | N13: [1] 27.88994 28.26514 27.73501 27.33193 26.36425 25.39481 24.34116 24.50707 24.17464 23.52041
A14: 2002 | B14: 37.765057 | D14: 39.408398 | F14: 22.948118 | H14: 18.854721 | J14: 58.855015 | N14: [11] 23.51826 23.53861 23.54323 22.84256 22.22810 21.66320 21.02909 20.70000 21.19554 20.89714
A15: 2003 | B15: 37.09893 | D15: 39.153561 | F15: 22.669794 | H15: 18.682375 | J15: 57.725449 | N15: [21] 20.26986 20.40082 20.29084 19.93929 19.32157 18.62563 17.91610 17.51794 17.32306
A16: 2004 | B16: 36.318214 | D16: 39.013535 | F16: 22.303991 | H16: 18.501169 | J16: 56.764675
A17: 2005 | B17: 35.509972 | D17: 38.887638 | F17: 21.795887 | H17: 18.253489 | J17: 55.824493 | N17: Indonesia
A18: 2006 | B18: 34.688599 | D18: 38.631592 | F18: 21.266304 | H18: 18.02516 | J18: 54.842567 | N18: [1] 18.91444 18.65533 18.63413 18.36731 18.32199 18.05829 17.95741 17.74400 20.54421 20.47115
A19: 2007 | B19: 34.100784 | D19: 38.300793 | F19: 20.700939 | H19: 17.90032 | J19: 53.700935 | N19: [11] 20.07676 19.79270 19.53969 19.28114 18.80937 18.38622 18.18133 17.90000 17.69556 17.86046
A20: 2008 | B20: 33.480824 | D20: 37.944885 | F20: 20.192965 | H20: 17.685661 | J20: 52.717163 | N20: [21] 17.46700 17.16400 17.15695 17.00471 16.84490 16.79993 16.58994 16.39857 16.33180
A21: 2009 | B21: 32.828964 | D21: 37.753368 | F21: 19.695469 | H21: 17.432539 | J21: 51.640076
A22: 2010 | B22: 32.177204 | D22: 37.923954 | F22: 19.275066 | H22: 17.270966 | J22: 50.98455
A23: 2011 | B23: 31.500191 | D23: 37.854187 | F23: 18.850731 | H23: 17.029758 | J23: 49.907074
A24: 2012 | B24: 30.899021 | D24: 37.773811 | F24: 18.458332 | H24: 16.739225 | J24: 48.764637
A25: 2013 | B25: 30.204218 | D25: 38.060898 | F25: 18.140812 | H25: 16.472683 | J25: 47.648808
A26: 2014 | B26: 29.5326 | D26: 37.880928 | F26: 17.840628 | H26: 16.233072 | J26: 46.858673
A27: 2015 | B27: 28.897316 | D27: 37.93914 | F27: 17.566015 | H27: 15.950048 | J27: 46.034599
A28: 2016 | B28: 28.256935 | D28: 38.033409 | F28: 17.269661 | H28: 15.743974 | J28: 44.925217
A29: 2017 | B29: 27.631273 | D29: 38.257103 | F29: 16.960295 | H29: 15.537893 | J29: 43.811855
A30: 2018 | B30: 26.998659 | D30: 38.204689 | F30: 16.653046 | H30: 15.284904 | J30: 42.647057

Sheet MIMIC_p
A1: Economy | B1: Code | C1: 1990 | D1: 1991 | E1: 1992 | F1: 1993 | G1: 1994 | H1: 1995 | I1: 1996 | J1: 1997 | K1: 1998 | L1: 1999 | M1: 2000 | N1: 2001 | O1: 2002 | P1: 2003 | Q1: 2004 | R1: 2005 | S1: 2006 | T1: 2007 | U1: 2008 | V1: 2009 | W1: 2010 | X1: 2011 | Y1: 2012 | Z1: 2013 | AA1: 2014 | AB1: 2015 | AC1: 2016 | AD1: 2017 | AE1: 2018 | AG1: avg 2005-2015
A2: Albania | B2: ALB | F2: 38.571281 | G2: 38.260952 | H2: 37.862961 | I2: 35.685631 | J2: 36.243999 | K2: 36.363335 | L2: 36.019932 | M2: 35.299999 | N2: 36.439022 | O2: 35.57333 | P2: 35.238903 | Q2: 35.024368 | R2: 34.94566 | S2: 34.391949 | T2: 34.177273 | U2: 33.751469 | V2: 33.956642 | W2: 33.877605 | X2: 33.597435 | Y2: 33.505386 | Z2: 33.804462 | AA2: 33.753948 | AB2: 33.51561 | AC2: 33.233231 | AD2: 32.931488 | AE2: 32.407963 | AG2: =AVERAGE($R2:$AB2) -> 33.934313
A3: Algeria | B3: DZA | F3: 34.984856 | G3: 35.057541 | H3: 34.919014 | I3: 35.023457 | J3: 34.944878 | K3: 34.79649 | L3: 34.587124 | M3: 34.099998 | N3: 33.896748 | O3: 33.497978 | P3: 32.91909 | Q3: 32.373051 | R3: 31.381727 | S3: 31.241148 | T3: 31.308382 | U3: 31.496702 | V3: 31.918821 | W3: 31.838108 | X3: 32.420799 | Y3: 32.238972 | Z3: 31.941799 | AA3: 31.831318 | AB3: 32.040489 | AC3: 31.830296 | AD3: 31.742619 | AE3: 31.315495 | AG3: =AVERAGE($R3:$AB3) -> 31.787115
A4: Angola | B4: AGO | F4: 50.773422 | G4: 49.773392 | H4: 47.836201 | I4: 47.405991 | J4: 47.323349 | K4: 49.990227 | L4: 47.678768 | M4: 48.799999 | N4: 48.596016 | O4: 46.689796 | P4: 46.970917 | Q4: 46.379879 | R4: 45.360245 | S4: 45.261456 | T4: 44.122997 | U4: 43.668079 | V4: 44.13237 | W4: 44.137409 | X4: 44.295761 | Y4: 43.62915 | Z4: 44.187042 | AA4: 43.451481 | AB4: 43.223419 | AC4: 43.443283 | AD4: 43.384041 | AE4: 43.328171 | AG4: =AVERAGE($R4:$AB4) -> 44.133583
A5: Argentina | B5: ARG | F5: 25.562576 | G5: 25.373232 | H5: 25.952002 | I5: 25.319374 | J5: 24.688923 | K5: 24.432482 | L5: 25.105556 | M5: 25.4 | N5: 26.03927 | O5: 26.41473 | P5: 25.656591 | Q5: 25.065067 | R5: 24.802246 | S5: 24.373484 | T5: 23.895636 | U5: 23.884768 | V5: 24.921953 | W5: 24.042017 | X5: 23.749647 | Y5: 24.167986 | Z5: 24.134323 | AA5: 24.369669 | AB5: 24.415709 | AC5: 24.373549 | AD5: 24.294239 | AE5: 24.408112 | AG5: =AVERAGE($R5:$AB5) -> 24.250676
A6: Armenia | B6: ARM | F6: 49.078381 | G6: 46.229176 | H6: 46.409405 | I6: 46.283585 | J6: 46.210648 | K6: 46.16127 | L6: 46.370132 | M6: 46.299999 | N6: 46.569958 | O6: 45.144955 | P6: 45.033127 | Q6: 44.915134 | R6: 44.366032 | S6: 44.015175 | T6: 43.682785 | U6: 42.372223 | V6: 43.75029 | W6: 43.842625 | X6: 43.489197 | Y6: 42.941334 | Z6: 42.905033 | AA6: 43.296852 | AB6: 43.481316 | AC6: 43.56078 | AD6: 42.755604 | AE6: 42.493435 | AG6: =AVERAGE($R6:$AB6) -> 43.467533
A7: Australia | B7: AUS | F7: 15.538859 | G7: 15.193089 | H7: 15.083937 | I7: 14.748693 | J7: 14.710875 | K7: 14.797376 | L7: 14.473602 | M7: 14.3 | N7: 14.230507 | O7: 14.17737 | P7: 13.947599 | Q7: 13.720336 | R7: 13.790193 | S7: 13.695948 | T7: 13.417634 | U7: 13.541302 | V7: 13.900376 | W7: 13.716012 | X7: 13.81276 | Y7: 13.723848 | Z7: 13.637008 | AA7: 13.820518 | AB7: 14.116594 | AC7: 14.018482 | AD7: 14.087063 | AE7: 14.065775 | AG7: =AVERAGE($R7:$AB7) -> 13.742927
A8: Austria | B8: AUT | F8: 10.522746 | G8: 10.405677 | H8: 10.410053 | I8: 10.39249 | J8: 10.339491 | K8: 10.204848 | L8: 10.129485 | M8: 9.8000002 | N8: 9.7051287 | O8: 9.6750154 | P8: 9.7274609 | Q8: 9.7564936 | R8: 9.9559669 | S8: 9.7178679 | T8: 9.3870134 | U8: 9.4718151 | V8: 10.237248 | W8: 10.010277 | X8: 9.7683134 | Y8: 9.7893171 | Z8: 9.9001703 | AA8: 9.8861408 | AB8: 9.9220905 | AC8: 9.8845263 | AD8: 9.7171583 | AE8: 9.5145226 | AG8: =AVERAGE($R8:$AB8) -> 9.8223837
A9: Azerbaijan | B9: AZE | F9: 62.281738 | G9: 61.244701 | H9: 59.083519 | I9: 58.800266 | J9: 59.293415 | K9: 59.825024 | L9: 59.419659 | M9: 60.599998 | N9: 59.940506 | O9: 59.324497 | P9: 58.786858 | Q9: 58.432869 | R9: 57.220524 | S9: 55.714382 | T9: 55.136238 | U9: 54.435043 | V9: 54.396973 | W9: 54.318825 | X9: 54.241699 | Y9: 54.249496 | Z9: 53.555157 | AA9: 53.492989 | AB9: 53.671539 | AC9: 53.886753 | AD9: 53.678364 | AE9: 53.32856 | AG9: =AVERAGE($R9:$AB9) -> 54.584806
A10: Bahamas, The | B10: BHS | F10: 29.529099 | G10: 29.808674 | H10: 29.047697 | I10: 28.395842 | J10: 28.279943 | K10: 27.515125 | L10: 26.590883 | M10: 26.200001 | N10: 26.125566 | O10: 26.079443 | P10: 26.742794 | Q10: 26.976254 | R10: 26.674578 | S10: 26.567511 | T10: 26.657625 | U10: 27.625893 | V10: 29.381832 | W10: 29.326618 | X10: 29.773483 | Y10: 29.328648 | Z10: 30.001028 | AA10: 29.938717 | AB10: 29.888584 | AC10: 29.751982 | AD10: 30.211302 | AE10: 29.955345 | AG10: =AVERAGE($R10:$AB10) -> 28.65132
A11: Bahrain | B11: BHR | F11: 19.940973 | G11: 20.086643 | H11: 19.875603 | I11: 19.157866 | J11: 19.145502 | K11: 18.90955 | L11: 18.748293 | M11: 18.4 | N11: 19.011644 | O11: 19.468067 | P11: 19.422318 | Q11: 19.201565 | R11: 19.174101 | S11: 19.215986 | T11: 19.528322 | U11: 19.209087 | V11: 20.337887 | W11: 20.190607 | X11: 20.581583 | Y11: 20.236902 | Z11: 19.305143 | AA11: 18.840113 | AB11: 18.974283 | AC11: 19.129181 | AD11: 19.348269 | AE11: 19.976244 | AG11: =AVERAGE($R11:$AB11) -> 19.599456
A12: Bangladesh | B12: BGD | F12: 36.670769 | G12: 36.484997 | H12: 36.079762 | I12: 35.634632 | J12: 35.429028 | K12: 35.365761 | L12: 35.496166 | M12: 35.599998 | N12: 35.585888 | O12: 36.180836 | P12: 36.863773 | Q12: 37.21397 | R12: 37.185455 | S12: 36.700558 | T12: 36.212723 | U12: 35.93232 | V12: 36.021946 | W12: 35.543152 | X12: 35.391773 | Y12: 35.197815 | Z12: 35.04422 | AA12: 34.929951 | AB12: 34.645958 | AC12: 34.769283 | AD12: 34.658211 | AE12: 34.653992 | AG12: =AVERAGE($R12:$AB12) -> 35.709625
A13: Belarus | B13: BLR | F13: 48.233044 | G13: 49.061348 | H13: 49.321892 | I13: 48.788235 | J13: 48.625355 | K13: 48.434925 | L13: 48.251743 | M13: 48.099998 | N13: 48.687191 | O13: 48.558594 | P13: 48.426464 | Q13: 47.986183 | R13: 47.696613 | S13: 46.90324 | T13: 46.326855 | U13: 45.295944 | V13: 45.331703 | W13: 44.917881 | X13: 43.83894 | Y13: 43.577366 | Z13: 43.492977 | AA13: 43.092228 | AB13: 42.861843 | AC13: 43.225697 | AD13: 42.924915 | AE13: 42.565437 | AG13: =AVERAGE($R13:$AB13) -> 44.84869
... A48: Equatorial Guinea | B48: GNQ | F48: 34.590435 | G48: 34.000645 | H48: 34.17503 | I48: 33.351429 | J48: 32.908165 | K48: 33.697369 | L48: 33.007206 | M48: 32.799999 | N48: 31.990612 | O48: 31.955618 | P48: 32.098701 | Q48: 31.580488 | R48: 31.401777 | S48: 31.4835 | T48: 31.284048 | U48: 30.827639 | V48: 31.424809 | W48: 31.877401 | X48: 31.736187 | Y48: 31.583359 | Z48: 32.119236 | AA48: 32.62289 | AB48: 33.330757 | AC48: 33.878975 | AD48: 33.865742 | AE48: 33.709209 | AG48: =AVERAGE($R48:$AB48) -> 31.790146
A49: Eritrea | B49: ERI | F49: 39.923378 | G49: 38.655334 | H49: 39.699898 | I49: 38.712605 | J49: 37.859909 | K49: 38.943405 | L49: 39.194004 | M49: 40.299999 | N49: 38.846722 | O49: 38.805672 | P49: 39.829224 | Q49: 39.353527 | R49: 39.285519 | S49: 39.228226 | T49: 39.116776 | U49: 39.824951 | V49: 39.161404 | W49: 39.343468 | X49: 38.654224 | Y49: 40.782795 | Z49: 41.242008 | AA49: 40.801228 | AB49: 41.248825 | AC49: 41.161804 | AG49: =AVERAGE($R49:$AB49) -> 39.880857
A50: Estonia | B50: EST | F50: 32.895302 | G50: 33.649742 | H50: 34.233429 | I50: 33.868534 | J50: 33.120659 | K50: 33.024975 | L50: 33.45097 | M50: 32.700001 | N50: 32.254807 | O50: 31.713985 | P50: 31.299526 | Q50: 30.919613 | R50: 30.257725 | S50: 29.310369 | T50: 29.032091 | U50: 29.806387 | V50: 31.741158 | W50: 31.541521 | X50: 30.62048 | Y50: 30.37085 | Z50: 30.280943 | AA50: 30.061119 | AB50: 30.036377 | AC50: 30.031496 | AD50: 29.569256 | AE50: 29.188324 | AG50: =AVERAGE($R50:$AB50) -> 30.278093
A51: Eswatini | B51: SWZ | F51: 42.588673 | G51: 42.479454 | H51: 41.556015 | I51: 41.910141 | J51: 42.73835 | K51: 42.676102 | L51: 42.442772 | M51: 41.400002 | N51: 41.350368 | O51: 40.688091 | P51: 41.262386 | Q51: 42.08382 | R51: 41.591122 | S51: 40.772919 | T51: 40.707748 | U51: 41.060356 | V51: 41.190441 | W51: 40.480717 | X51: 40.221882 | Y51: 39.281021 | Z51: 38.835026 | AA51: 39.160713 | AB51: 39.274418 | AC51: 39.486187 | AD51: 39.37006 | AE51: 38.931454 | AG51: =AVERAGE($R51:$AB51) -> 40.234215
A52: Ethiopia | B52: ETH | F52: 37.729801 | G52: 38.179462 | H52: 38.496284 | I52: 38.04438 | J52: 38.119766 | K52: 38.71513 | L52: 40.098007 | M52: 40.299999 | N52: 39.361347 | O52: 39.290134 | P52: 38.945591 | Q52: 38.475048 | R52: 38.28656 | S52: 37.797783 | T52: 37.037003 | U52: 36.623104 | V52: 36.339191 | W52: 35.956951 | X52: 35.950001 | Y52: 35.424263 | Z52: 35.271137 | AA52: 34.911129 | AB52: 34.749935 | AC52: 34.824413 | AD52: 34.531898 | AE52: 34.053925 | AG52: =AVERAGE($R52:$AB52) -> 36.213369
A53: Fiji | B53: FJI | F53: 34.703884 | G53: 33.41674 | H53: 33.073414 | I53: 32.798054 | J53: 33.489349 | K53: 34.067001 | L53: 32.840935 | M53: 33.599998 | N53: 33.104153 | O53: 32.430004 | P53: 32.862324 | Q53: 31.82324 | R53: 31.429987 | S53: 32.848927 | T53: 32.947742 | U53: 32.510925 | V53: 33.330368 | W53: 32.144638 | X53: 32.991554 | Y53: 33.59528 | Z53: 33.262768 | AA53: 32.244923 | AB53: 31.867552 | AC53: 31.490891 | AD53: 30.599731 | AE53: 30.081411 | AG53: =AVERAGE($R53:$AB53) -> 32.652242
A54: Finland | B54: FIN | F54: 20.236776 | G54: 19.963459 | H54: 19.690584 | I54: 19.796919 | J54: 19.250158 | K54: 18.768951 | L54: 18.46339 | M54: 18.1 | N54: 17.994543 | O54: 18.04262 | P54: 17.982567 | Q54: 17.896631 | R54: 17.840862 | S54: 17.591902 | T54: 17.364332 | U54: 17.41762 | V54: 18.261625 | W54: 18.076599 | X54: 17.878872 | Y54: 18.113913 | Z54: 18.319569 | AA54: 18.495827 | AB54: 18.629486 | AC54: 18.354671 | AD54: 17.978682 | AE54: 17.786581 | AG54: =AVERAGE($R54:$AB54) -> 17.999146
A55: France | B55: FRA | F55: 16.808504 | G55: 16.706005 | H55: 16.540771 | I55: 16.781889 | J55: 16.571392 | K55: 15.953897 | L55: 15.715094 | M55: 15.2 | N55: 14.967157 | O55: 15.212767 | P55: 15.290254 | Q55: 15.120858 | R55: 15.118074 | S55: 14.899965 | T55: 14.698662 | U55: 14.652357 | V55: 15.673038 | W55: 15.589509 | X55: 15.418811 | Y55: 15.575553 | Z55: 15.578229 | AA55: 15.5667 | AB55: 15.383033 | AC55: 15.304152 | AD55: 15.115433 | AE55: 14.7885 | AG55: =AVERAGE($R55:$AB55) -> 15.286721
A56: Gabon | B56: GAB | F56: 47.780609 | G56: 46.45858 | H56: 46.257202 | I56: 45.503902 | J56: 45.281872 | K56: 47.176167 | L56: 48.071808 | M56: 48 | N56: 50.455395 | O56: 50.916649 | P56: 51.036034 | Q56: 51.42762 | R56: 50.506195 | S56: 51.724369 | T56: 51.44632 | U56: 52.039742 | V56: 53.889885 | W56: 52.029057 | X56: 51.299271 | Y56: 51.704136 | Z56: 51.488358 | AA56: 51.023014 | AB56: 51.035278 | AC56: 51.17149 | AD56: 51.114414 | AE56: 50.099693 | AG56: =AVERAGE($R56:$AB56) -> 51.653238
A57: Gambia, The | B57: GMB | F57: 47.238285 | G57: 46.955162 | H57: 48.152683 | I57: 48.0994 | J57: 47.197857 | K57: 46.309181 | L57: 45.312664 | M57: 45.099998 | N57: 44.37241 | O57: 46.711586 | P57: 44.027744 | Q57: 42.318363 | R57: 45.326889 | S57: 46.405201 | T57: 45.959316 | U57: 45.964386 | V57: 44.171814 | W57: 43.324543 | X57: 47.646778 | Y57: 45.969437 | Z57: 46.631416 | AA57: 48.898102 | AB57: 49.629932 | AC57: 49.335735 | AD57: 48.197247 | AE57: 46.844101 | AG57: =AVERAGE($R57:$AB57) -> 46.357074
A58: Georgia | B58: GEO | F58: 67.899231 | G58: 68.917427 | H58: 69.345604 | I58: 68.211494 | J58: 68.359787 | K58: 68.430298 | L58: 68.566177 | M58: 67.300003 | N58: 67.490028 | O58: 67.712303 | P58: 66.736633 | Q58: 67.760674 | R58: 68.251465 | S58: 67.19072 | T58: 67.574806 | U58: 68.913315 | V58: 68.881569 | W58: 66.38932 | X58: 65.091164 | Y58: 64.537537 | Z58: 64.265884 | AA58: 63.779556 | AB58: 63.28698 | AC58: 63.22044 | AD58: 61.828232 | AE58: 61.235229 | AG58: =AVERAGE($R58:$AB58) -> 66.196574
A59: Germany | B59: DEU | F59: 16.882622 | G59: 16.79953 | H59: 16.780973 | I59: 16.867733 | J59: 16.619757 | K59: 16.32127 | L59: 16.262291 | M59: 16 | N59: 15.945912 | O59: 16.196968 | P59: 16.530506 | Q59: 16.238886 | R59: 16.21093 | S59: 15.66153 | T59: 15.199259 | U59: 15.348127 | V59: 16.420113 | W59: 15.973832 | X59: 15.380827 | Y59: 15.410168 | Z59: 15.597274 | AA59: 15.325316 | AB59: 15.239039 | AC59: 15.236104 | AD59: 15.139071 | AE59: 15.140614 | AG59: =AVERAGE($R59:$AB59) -> 15.615129
A60: Ghana | B60: GHA | F60: 43.884502 | G60: 43.298973 | H60: 42.537716 | I60: 43.054867 | J60: 42.87151 | K60: 42.279804 | L60: 42.320477 | M60: 41.900002 | N60: 41.854 | O60: 41.979088 | P60: 42.418999 | Q60: 42.375874 | R60: 42.843765 | S60: 40.018551 | T60: 39.834785 | U60: 39.923439 | V60: 39.456657 | W60: 39.284843 | X60: 40.576729 | Y60: 39.47414 | Z60: 38.858101 | AA60: 39.123665 | AB60: 38.802185 | AC60: 38.241268 | AD60: 37.591099 | AE60: 37.569698 | AG60: =AVERAGE($R60:$AB60) -> 39.836078
A61: Greece | B61: GRC | F61: 29.465055 | G61: 29.229128 | H61: 29.601931 | I61: 29.172876 | J61: 28.971531 | K61: 28.778118 | L61: 28.817793 | M61: 28.700001 | N61: 28.44533 | O61: 28.23089 | P61: 27.785994 | Q61: 27.440987 | R61: 27.688377 | S61: 27.319141 | T61: 27.19701 | U61: 27.257978 | V61: 28.336081 | W61: 28.691645 | X61: 29.517574 | Y61: 30.380508 | Z61: 30.202448 | AA61: 30.093637 | AB61: 30.167677 | AC61: 30.076464 | AD61: 29.756443 | AE61: 29.349083 | AG61: =AVERAGE($R61:$AB61) -> 28.804734
... A64: Guinea-Bissau | B64: GNB | F64: 36.162037 | G64: 36.03561 | H64: 35.906475 | I64: 34.570152 | J64: 33.924778 | K64: 39.628292 | L64: 38.714622 | M64: 39.599998 | N64: 38.944996 | O64: 39.577351 | P64: 40.260143 | Q64: 40.038914 | R64: 39.540386 | S64: 38.992599 | T64: 38.506336 | U64: 38.071236 | V64: 37.969997 | W64: 37.823467 | X64: 37.135174 | Y64: 38.31971 | Z64: 37.703564 | AA64: 39.502117 | AB64: 38.623943 | AC64: 37.868069 | AD64: 37.314907 | AE64: 36.779396 | AG64: =AVERAGE($R64:$AB64) -> 38.380775
A65: Guyana | B65: GUY | F65: 33.941936 | G65: 33.676575 | H65: 33.394394 | I65: 33.433624 | J65: 32.985542 | K65: 32.791878 | L65: 32.825356 | M65: 33.599998 | N65: 33.706646 | O65: 33.89185 | P65: 34.165852 | Q65: 33.849804 | R65: 34.888435 | S65: 32.282322 | T65: 31.305849 | U65: 32.049911 | V65: 31.747177 | W65: 31.221716 | X65: 30.863459 | Y65: 30.460287 | Z65: 30.450378 | AA65: 30.553844 | AB65: 30.602676 | AC65: 30.41968 | AG65: =AVERAGE($R65:$AB65) -> 31.493278
A66: Haiti | B66: HTI | F66: 54.502056 | G66: 61.113167 | H66: 58.28516 | I66: 56.328419 | J66: 56.63961 | K66: 56.044338 | L66: 54.825565 | M66: 55.400002 | N66: 56.859928 | O66: 58.096386 | P66: 58.456646 | Q66: 60.733856 | R66: 60.784271 | S66: 59.804379 | T66: 58.640224 | U66: 59.822994 | V66: 59.413139 | W66: 61.745842 | X66: 61.000668 | Y66: 60.50005 | Z66: 59.157848 | AA66: 59.244221 | AB66: 59.71003 | AC66: 60.003811 | AD66: 59.705265 | AE66: 59.085697 | AG66: =AVERAGE($R66:$AB66) -> 59.98397
A67: Honduras | B67: HND | F67: 49.333424 | G67: 49.345276 | H67: 48.852615 | I67: 49.993649 | J67: 48.752342 | K67: 49.064716 | L67: 49.76181 | M67: 49.599998 | N67: 50.168167 | O67: 50.136646 | P67: 50.6646 | Q67: 50.559044 | R67: 49.568306 | S67: 48.276863 | T67: 47.80175 | U67: 47.986767 | V67: 49.374966 | W67: 49.515209 | X67: 48.184029 | Y67: 48.257557 | Z67: 48.324944 | AA67: 48.005314 | AB67: 47.750397 | AC67: 47.328854 | AD67: 45.464218 | AE67: 45.554008 | AG67: =AVERAGE($R67:$AB67) -> 48.458736
A68: Hungary | B68: HUN | F68: 27.897995 | G68: 27.198603 | H68: 26.529018 | I68: 26.081352 | J68: 25.753767 | K68: 25.427734 | L68: 25.325394 | M68: 25.1 | N68: 24.835262 | O68: 24.787189 | P68: 24.932533 | Q68: 24.604818 | R68: 24.585865 | S68: 24.302431 | T68: 24.147604 | U68: 24.244118 | V68: 24.905844 | W68: 24.85535 | X68: 24.546848 | Y68: 24.488255 | Z68: 24.245667 | AA68: 24.004814 | AB68: 23.705143 | AC68: 23.537296 | AD68: 23.215511 | AE68: 22.775291 | AG68: =AVERAGE($R68:$AB68) -> 24.36654
A69: Iceland | B69: ISL | F69: 16.523705 | G69: 16.431404 | H69: 16.499861 | I69: 16.240894 | J69: 16.108965 | K69: 15.927001 | L69: 15.91927 | M69: 15.9 | N69: 15.856474 | O69: 16.218407 | P69: 16.270252 | Q69: 15.858902 | R69: 15.663559 | S69: 15.604206 | T69: 15.250415 | U69: 15.382854 | V69: 16.24843 | W69: 16.364605 | X69: 16.272186 | Y69: 16.167814 | Z69: 15.970172 | AA69: 15.865016 | AB69: 15.576094 | AC69: 15.221318 | AD69: 15.202729 | AE69: 15.147697 | AG69: =AVERAGE($R69:$AB69) -> 15.851396
A70: India | B70: IND | F70: 22.902859 | G70: 22.243155 | H70: 22.394056 | I70: 22.282246 | J70: 22.687395 | K70: 23.024748 | L70: 23.253344 | M70: 23.1 | N70: 22.817043 | O70: 22.685339 | P70: 22.151052 | Q70: 21.887848 | R70: 21.939844 | S70: 21.483025 | T70: 20.885742 | U70: 21.547546 | V70: 21.804804 | W70: 21.196896 | X70: 21.172609 | Y70: 21.109091 | Z70: 20.783535 | AA70: 20.740847 | AB70: 20.204659 | AC70: 19.932491 | AD70: 20.066374 | AE70: 19.729753 | AG70: =AVERAGE($R70:$AB70) -> 21.169872
A71: Indonesia | B71: IDN | F71: 20.102558 | G71: 19.805298 | H71: 19.512468 | I71: 19.583506 | J71: 19.31962 | K71: 19.358456 | L71: 19.582167 | M71: 19.4 | N71: 19.6234 | O71: 19.762365 | P71: 19.979429 | Q71: 19.956011 | R71: 19.933475 | S71: 19.834019 | T71: 19.530622 | U71: 19.366785 | V71: 19.588867 | W71: 19.205591 | X71: 19.075899 | Y71: 18.963539 | Z71: 18.881798 | AA71: 18.647932 | AB71: 18.724573 | AC71: 18.38983 | AD71: 18.110592 | AE71: 17.884134 | AG71: =AVERAGE($R71:$AB71) -> 19.250282
A72: Iran, Islamic Rep. | B72: IRN | F72: 19.369518 | G72: 19.460175 | H72: 19.398762 | I72: 19.150526 | J72: 18.80806 | K72: 19.057362 | L72: 18.766125 | M72: 18.9 | N72: 19.017946 | O72: 18.633118 | P72: 18.184938 | Q72: 17.792618 | R72: 18.212799 | S72: 17.994658 | T72: 17.125841 | U72: 17.277395 | V72: 17.586338 | W72: 17.423773 | X72: 17.086449 | Y72: 17.517382 | Z72: 17.642771 | AA72: 17.466387 | AB72: 17.883301 | AC72: 17.626982 | AD72: 17.500916 | AE72: 17.762594 | AG72: =AVERAGE($R72:$AB72) -> 17.56519
A73: Ireland | B73: IRL | F73: 17.520372 | G73: 17.409039 | H73: 17.113577 | I73: 16.838339 | J73: 16.566536 | K73: 16.274158 | L73: 16.060955 | M73: 15.9 | N73: 15.904167 | O73: 15.898274 | P73: 15.955291 | Q73: 15.882673 | R73: 15.659989 | S73: 15.769278 | T73: 15.778559 | U73: 16.2202 | V73: 16.777746 | W73: 16.644983 | X73: 16.543943 | Y73: 16.415398 | Z73: 16.314213 | AA73: 15.936738 | AB73: 14.963449 | AC73: 14.995302 | AD73: 14.743145 | AE73: 14.404099 | AG73: =AVERAGE($R73:$AB73) -> 16.093136
A74: Israel | B74: ISR | F74: 23.195154 | G74: 22.719151 | H74: 22.716702 | I74: 22.995506 | J74: 22.78887 | K74: 22.532972 | L74: 22.430666 | M74: 21.9 | N74: 22.326056 | O74: 22.810287 | P74: 22.627851 | Q74: 22.138081 | R74: 21.994642 | S74: 21.489452 | T74: 20.988714 | U74: 20.73102 | V74: 20.963779 | W74: 20.529436 | X74: 20.250113 | Y74: 20.445072 | Z74: 20.269644 | AA74: 20.151825 | AB74: 19.858934 | AC74: 19.710121 | AD74: 19.569618 | AE74: 19.66255 | AG74: =AVERAGE($R74:$AB74) -> 20.697512
A75: Italy | B75: ITA | F75: 30.580818 | G75: 29.995689 | H75: 28.973577 | I75: 28.638283 | J75: 28.368341 | K75: 27.989559 | L75: 27.721178 | M75: 27.1 | N75: 26.924555 | O75: 26.917469 | P75: 27.143864 | Q75: 27.108978 | R75: 27.308575 | S75: 27.035728 | T75: 26.700823 | U75: 27.255178 | V75: 28.857277 | W75: 28.593012 | X75: 28.205343 | Y75: 28.993444 | Z75: 29.640575 | AA75: 29.772015 | AB75: 29.302025 | AC75: 28.923199 | AD75: 28.481583 | AE75: 28.414623 | AG75: =AVERAGE($R75:$AB75) -> 28.333091
A76: Jamaica | B76: JAM | F76: 33.357243 | G76: 32.751976 | H76: 32.451801 | I76: 33.571476 | J76: 34.930058 | K76: 36.497948 | L76: 36.23716 | M76: 36.400002 | N76: 36.225082 | O76: 35.782207 | P76: 34.073288 | Q76: 33.184425 | R76: 33.756836 | S76: 32.041576 | T76: 31.827669 | U76: 32.923763 | V76: 35.284767 | W76: 36.084236 | X76: 35.534836 | Y76: 36.55547 | Z76: 36.460953 | AA76: 35.815968 | AB76: 35.287888 | AC76: 34.687286 | AD76: 34.089149 | AE76: 33.23048 | AG76: =AVERAGE($R76:$AB76) -> 34.688542
...

Sheet Sheet1
B4: Economy | C4: Bangladesh | D4: Bangladesh
B5: Code | C5: BGD | D5: BGD
B6: 1990 | D6: 42.95211
B7: 1991 | D7: 42.664642
B8: 1992 | D8: 42.45015
B9: 1993 | C9: 36.670769 | D9: 42.107204
B10: 1994 | C10: 36.484997 | D10: 41.800095
B11: 1995 | C11: 36.079762 | D11: 41.484585
B12: 1996 | C12: 35.634632 | D12: 41.130989
B13: 1997 | C13: 35.429028 | D13: 40.773449
B14: 1998 | C14: 35.365761 | D14: 40.172474
B15: 1999 | C15: 35.496166 | D15: 39.560257
B16: 2000 | C16: 35.599998 | D16: 38.955914
B17: 2001 | C17: 35.585888 | D17: 38.389839
B18: 2002 | C18: 36.180836 | D18: 37.765057
B19: 2003 | C19: 36.863773 | D19: 37.09893
B20: 2004 | C20: 37.21397 | D20: 36.318214
... B34: 2018 | C34: 34.653992 | D34: 26.998659

Sheet SEMP_p
A1: Economy | B1: Code | C1: 1990 | D1: 1991 | E1: 1992 | F1: 1993 | G1: 1994 | H1: 1995 | I1: 1996 | J1: 1997 | K1: 1998 | L1: 1999 | M1: 2000 | N1: 2001 | O1: 2002 | P1: 2003 | Q1: 2004 | R1: 2005 | S1: 2006 | T1: 2007 | U1: 2008 | V1: 2009 | W1: 2010 | X1: 2011 | Y1: 2012 | Z1: 2013 | AA1: 2014 | AB1: 2015 | AC1: 2016 | AD1: 2017 | AE1: 2018 | AG1: avg 2005-2015
A2: Albania | B2: ALB | O2: 65.301247 | P2: 66.666664 | Q2: 66.136833 | R2: 57.190403 | T2: 65.400002 | U2: 59.599998 | V2: 58.599998 | W2: 56.200001 | X2: 60.099998 | Y2: 62.900002 | Z2: 59.799999 | AA2: 58.400002 | AB2: 59 | AC2: 58.799999 | AD2: 55.900002 | AE2: 55.5 | AG2: =AVERAGE($R2:$AB2) -> 59.71904
A3: Algeria | B3: DZA | P3: 34.999977 | Q3: 39.897957 | R3: 34.374931 | S3: 39.900307 | T3: 34.969978 | U3: 34.248222 | V3: 34.153294 | W3: 33.394966 | X3: 32.972183 | Y3: 30.471977 | Z3: 31.034483 | AA3: 29.065338 | AB3: 30.17746 | AG3: =AVERAGE($R3:$AB3) -> 33.160285
A4: Angola | B4: AGO | V4: 79.199997 | AA4: 56.996838 | AG4: =AVERAGE($R4:$AB4) -> 68.098417
A5: Antigua and Barbuda | B5: ATG | D5: 18.6 | N5: 11.7 | AG5: =AVERAGE($R5:$AB5) -> #DIV/0!
A6: Argentina | B6: ARG | C6: 31 | D6: 29.700001 | E6: 29.799999 | F6: 31.200001 | G6: 29.799999 | H6: 29.4 | I6: 29.200001 | J6: 28.200001 | K6: 27.799999 | L6: 27.6 | M6: 27.6 | N6: 28.200001 | O6: 28.299999 | P6: 26.299999 | Q6: 25.9 | R6: 25.5 | S6: 24.200001 | T6: 23.6 | U6: 23.700001 | V6: 24 | W6: 23.6 | X6: 23.1 | Y6: 23 | Z6: 24.700001 | AA6: 21.241369 | AB6: 21.651369 | AC6: 22.297369 | AD6: 21.905371 | AG6: =AVERAGE($R6:$AB6) -> 23.481158
A7: Armenia | B7: ARM | J7: 42.603119 | K7: 44.948776 | L7: 46.156216 | M7: 47.178524 | N7: 35.099922 | O7: 49.963848 | P7: 51.119537 | Q7: 52.371269 | R7: 51.785389 | S7: 51.162579 | T7: 41.799999 | U7: 29.799999 | V7: 25.700001 | W7: 28 | X7: 30.4 | Y7: 29 | Z7: 42.799999 | AA7: 44.200001 | AB7: 42.799999 | AC7: 42 | AD7: 40.400002 | AE7: 37.400002 | AG7: =AVERAGE($R7:$AB7) -> 37.949815
A8: Aruba | B8: ABW | D8: 7.6999998 | J8: 0.48192772 | M8: 10 | T8: 8.8999996 | W8: 9.8000002 | AG8: =AVERAGE($R8:$AB8) -> 9.3499999
A9: Australia | B9: AUS | C9: 14.43366 | D9: 14.94005 | E9: 15.03843 | F9: 15.35481 | G9: 14.87992 | H9: 14.55846 | I9: 14.23104 | J9: 14.17805 | K9: 13.68025 | L9: 13.66896 | M9: 13.52428 | N9: 13.36004 | O9: 13.49648 | P9: 13.12908 | Q9: 12.79167 | R9: 12.59697 | S9: 12.08922 | T9: 11.68755 | U9: 11.47017 | V9: 11.52073 | W9: 11.51698 | X9: 11.07515 | Y9: 10.3881 | Z9: 10.11097 | AA9: 10.20161 | AB9: 10.31022 | AC9: 10.07958 | AD9: 9.9490805 | AE9: 9.6467228 | AG9: =AVERAGE($R9:$AB9) -> 11.178879
